2021-09-05 19:28:29,881 - conftest.py:logger - CRITICAL - Find test run artifacts at: C:\Users\siddh\Google Drive\PycharmProjects\nopAdminSelenium\TestRuns\Test Run - 2021-09-05 19.28.29.871199\
2021-09-05 19:28:29,928 - conftest.py:logger - CRITICAL - Find test run artifacts at: C:\Users\siddh\Google Drive\PycharmProjects\nopAdminSelenium\TestRuns\Test Run - 2021-09-05 19.28.29.871199\
2021-09-05 19:28:29,997 - conftest.py:logger - CRITICAL - Find test run artifacts at: C:\Users\siddh\Google Drive\PycharmProjects\nopAdminSelenium\TestRuns\Test Run - 2021-09-05 19.28.29.871199\
2021-09-05 19:28:30,059 - conftest.py:logger - CRITICAL - Find test run artifacts at: C:\Users\siddh\Google Drive\PycharmProjects\nopAdminSelenium\TestRuns\Test Run - 2021-09-05 19.28.29.871199\
2021-09-05 19:28:41,910 - test_addcustomer.py:setup - WARNING - Attempting login
2021-09-05 19:28:43,288 - test_addcustomer.py:setup - WARNING - Attempting login
2021-09-05 19:28:44,037 - test_addcustomer.py:setup - WARNING - Attempting login
2021-09-05 19:28:44,119 - test_addcustomer.py:setup - WARNING - Attempting login
2021-09-05 19:29:00,878 - test_addcustomer.py:setup - INFO - login successful
2021-09-05 19:29:02,669 - test_addcustomer.py:setup - INFO - login successful
2021-09-05 19:29:05,833 - test_addcustomer.py:setup - INFO - login successful
2021-09-05 19:29:37,063 - test_addcustomer.py:setup - WARNING - Attempting login
2021-09-05 19:29:41,916 - test_addcustomer.py:setup - WARNING - Attempting login
2021-09-05 19:29:47,023 - test_addcustomer.py:setup - WARNING - Attempting login
2021-09-05 19:29:58,136 - test_addcustomer.py:setup - INFO - login successful
2021-09-05 19:30:02,148 - test_addcustomer.py:setup - INFO - login successful
2021-09-05 19:30:02,864 - test_addcustomer.py:setup - INFO - login successful
2021-09-05 19:30:07,566 - test_addcustomer.py:setup - INFO - login successful
2021-09-05 19:30:21,416 - conftest.py:driver_class_scoped - ERROR - testCases/test_addcustomer.py::TestDropDownLists: An exception occurred while taking a screenshot
Traceback (most recent call last):
  File "C:\Users\siddh\Google Drive\PycharmProjects\nopAdminSelenium\testCases\conftest.py", line 154, in driver_class_scoped
    if all_test_functions[0].setup_result.failed:
AttributeError: 'Function' object has no attribute 'setup_result'
2021-09-05 19:30:29,183 - conftest.py:driver_class_scoped - ERROR - testCases/test_addcustomer.py::TestDropDownLists: An exception occurred while taking a screenshot
Traceback (most recent call last):
  File "C:\Users\siddh\Google Drive\PycharmProjects\nopAdminSelenium\testCases\conftest.py", line 158, in driver_class_scoped
    elif False in [test.call_result.passed for test in
  File "C:\Users\siddh\Google Drive\PycharmProjects\nopAdminSelenium\testCases\conftest.py", line 158, in <listcomp>
    elif False in [test.call_result.passed for test in
AttributeError: 'Function' object has no attribute 'call_result'
2021-09-05 19:30:32,404 - test_login.py:test_incorrect_password - INFO - Attempting login with useremail:ram@gmail.com and password:#$%rjry
2021-09-05 19:30:35,068 - test_login.py:test_incorrect_password - INFO - login failed as expected. Test DataRow no: 2
2021-09-05 19:30:38,467 - test_login.py:test_login - WARNING - Attempting login
2021-09-05 19:30:40,063 - test_addcustomer.py:setup - WARNING - Attempting login
2021-09-05 19:30:45,860 - test_login.py:test_incorrect_password - INFO - Attempting login with useremail:cold@hotmail.com and password:gh$%,k
2021-09-05 19:30:47,589 - test_login.py:test_incorrect_password - INFO - login failed as expected. Test DataRow no: 4
2021-09-05 19:30:51,212 - test_login.py:test_incorrect_password - INFO - Attempting login with useremail:mohan@yahoo.com and password:^3456kfg
2021-09-05 19:30:53,315 - test_login.py:test_login - INFO - login successful
2021-09-05 19:30:53,614 - test_login.py:test_incorrect_password - INFO - login failed as expected. Test DataRow no: 3
2021-09-05 19:31:15,809 - test_addcustomer.py:setup - INFO - login successful
2021-09-05 19:31:29,810 - conftest.py:driver_class_scoped - ERROR - testCases/test_addcustomer.py::TestDropDownLists: An exception occurred while taking a screenshot
Traceback (most recent call last):
  File "C:\Users\siddh\Google Drive\PycharmProjects\nopAdminSelenium\testCases\conftest.py", line 154, in driver_class_scoped
    if all_test_functions[0].setup_result.failed:
AttributeError: 'Function' object has no attribute 'setup_result'
